[2024-12-16T10:54:01.606+0000] {local_task_job_runner.py:123} INFO - ::group::Pre task execution logs
[2024-12-16T10:54:01.620+0000] {taskinstance.py:2613} INFO - Dependencies all met for dep_context=non-requeueable deps ti=<TaskInstance: check_server_status.check_server_status scheduled__2024-12-16T10:53:00+00:00 [queued]>
[2024-12-16T10:54:01.626+0000] {taskinstance.py:2613} INFO - Dependencies all met for dep_context=requeueable deps ti=<TaskInstance: check_server_status.check_server_status scheduled__2024-12-16T10:53:00+00:00 [queued]>
[2024-12-16T10:54:01.626+0000] {taskinstance.py:2866} INFO - Starting attempt 1 of 2
[2024-12-16T10:54:01.637+0000] {taskinstance.py:2889} INFO - Executing <Task(PythonOperator): check_server_status> on 2024-12-16 10:53:00+00:00
[2024-12-16T10:54:01.643+0000] {warnings.py:112} WARNING - /home/***/.local/lib/python3.12/site-packages/***/task/task_runner/standard_task_runner.py:70: DeprecationWarning: This process (pid=363) is multi-threaded, use of fork() may lead to deadlocks in the child.
  pid = os.fork()

[2024-12-16T10:54:01.644+0000] {standard_task_runner.py:72} INFO - Started process 365 to run task
[2024-12-16T10:54:01.645+0000] {standard_task_runner.py:104} INFO - Running: ['***', 'tasks', 'run', 'check_server_status', 'check_server_status', 'scheduled__2024-12-16T10:53:00+00:00', '--job-id', '98', '--raw', '--subdir', 'DAGS_FOLDER/check_server_status.py', '--cfg-path', '/tmp/tmpatxd524l']
[2024-12-16T10:54:01.646+0000] {standard_task_runner.py:105} INFO - Job 98: Subtask check_server_status
[2024-12-16T10:54:01.686+0000] {task_command.py:467} INFO - Running <TaskInstance: check_server_status.check_server_status scheduled__2024-12-16T10:53:00+00:00 [running]> on host 1b59279a9320
[2024-12-16T10:54:01.951+0000] {taskinstance.py:3132} INFO - Exporting env vars: AIRFLOW_CTX_DAG_OWNER='***' AIRFLOW_CTX_DAG_ID='check_server_status' AIRFLOW_CTX_TASK_ID='check_server_status' AIRFLOW_CTX_EXECUTION_DATE='2024-12-16T10:53:00+00:00' AIRFLOW_CTX_TRY_NUMBER='1' AIRFLOW_CTX_DAG_RUN_ID='scheduled__2024-12-16T10:53:00+00:00'
[2024-12-16T10:54:01.952+0000] {logging_mixin.py:190} INFO - Task instance is in running state
[2024-12-16T10:54:01.952+0000] {logging_mixin.py:190} INFO -  Previous state of the Task instance: queued
[2024-12-16T10:54:01.952+0000] {logging_mixin.py:190} INFO - Current task name:check_server_status state:running start_date:2024-12-16 10:54:01.620507+00:00
[2024-12-16T10:54:01.952+0000] {logging_mixin.py:190} INFO - Dag name:check_server_status and current dag run status:running
[2024-12-16T10:54:01.953+0000] {taskinstance.py:731} INFO - ::endgroup::
[2024-12-16T10:54:01.966+0000] {transport.py:1944} INFO - Connected (version 2.0, client OpenSSH_8.9p1)
[2024-12-16T10:54:02.077+0000] {transport.py:1944} INFO - Authentication (publickey) successful!
[2024-12-16T10:54:02.394+0000] {logging_mixin.py:190} INFO - Server 3rdLack MN is up
[2024-12-16T10:54:02.408+0000] {transport.py:1944} INFO - Connected (version 2.0, client OpenSSH_8.9p1)
[2024-12-16T10:54:02.538+0000] {transport.py:1944} INFO - Authentication (publickey) successful!
[2024-12-16T10:54:02.899+0000] {logging_mixin.py:190} INFO - Server 3rdLack SN05 is up
[2024-12-16T10:54:02.914+0000] {transport.py:1944} INFO - Connected (version 2.0, client OpenSSH_8.9p1)
[2024-12-16T10:54:03.027+0000] {transport.py:1944} INFO - Authentication (publickey) successful!
[2024-12-16T10:54:03.406+0000] {logging_mixin.py:190} INFO - Server 3rdLack SN06 is up
[2024-12-16T10:54:03.419+0000] {transport.py:1944} INFO - Connected (version 2.0, client OpenSSH_8.9p1)
[2024-12-16T10:54:03.521+0000] {transport.py:1944} INFO - Authentication (publickey) successful!
[2024-12-16T10:54:03.917+0000] {logging_mixin.py:190} INFO - Server 3rdLack SN07 is up
[2024-12-16T10:54:03.931+0000] {transport.py:1944} INFO - Connected (version 2.0, client OpenSSH_8.9p1)
[2024-12-16T10:54:04.032+0000] {transport.py:1944} INFO - Authentication (publickey) successful!
[2024-12-16T10:54:04.409+0000] {logging_mixin.py:190} INFO - Server 3rdLack SN08 is up
[2024-12-16T10:54:04.429+0000] {transport.py:1944} INFO - Connected (version 2.0, client OpenSSH_8.2p1)
[2024-12-16T10:54:04.495+0000] {transport.py:1944} INFO - Authentication (publickey) successful!
[2024-12-16T10:54:05.180+0000] {logging_mixin.py:190} INFO - Server 1rdLack MN is up
[2024-12-16T10:54:05.209+0000] {transport.py:1944} INFO - Connected (version 2.0, client OpenSSH_8.2p1)
[2024-12-16T10:54:05.275+0000] {transport.py:1944} INFO - Authentication (publickey) successful!
[2024-12-16T10:54:06.211+0000] {logging_mixin.py:190} INFO - Server 1rdLack SN01 is up
[2024-12-16T10:54:06.242+0000] {transport.py:1944} INFO - Connected (version 2.0, client OpenSSH_8.2p1)
[2024-12-16T10:54:06.324+0000] {transport.py:1944} INFO - Authentication (publickey) successful!
[2024-12-16T10:54:07.197+0000] {logging_mixin.py:190} INFO - Server 1rdLack SN02 is up
[2024-12-16T10:54:07.229+0000] {transport.py:1944} INFO - Connected (version 2.0, client OpenSSH_8.2p1)
[2024-12-16T10:54:07.315+0000] {transport.py:1944} INFO - Authentication (publickey) successful!
[2024-12-16T10:54:08.176+0000] {logging_mixin.py:190} INFO - Server 1rdLack SN03 is up
[2024-12-16T10:54:08.203+0000] {transport.py:1944} INFO - Connected (version 2.0, client OpenSSH_8.2p1)
[2024-12-16T10:54:08.274+0000] {transport.py:1944} INFO - Authentication (publickey) successful!
[2024-12-16T10:54:09.152+0000] {logging_mixin.py:190} INFO - Server 1rdLack SN04 is up
[2024-12-16T10:54:09.183+0000] {transport.py:1944} INFO - Connected (version 2.0, client OpenSSH_8.2p1)
[2024-12-16T10:54:09.273+0000] {transport.py:1944} INFO - Authentication (publickey) successful!
[2024-12-16T10:54:10.237+0000] {logging_mixin.py:190} INFO - Server 1rdLack SN05 is up
[2024-12-16T10:54:10.268+0000] {transport.py:1944} INFO - Connected (version 2.0, client OpenSSH_8.2p1)
[2024-12-16T10:54:10.375+0000] {transport.py:1944} INFO - Authentication (publickey) successful!
[2024-12-16T10:54:11.284+0000] {logging_mixin.py:190} INFO - Server 1rdLack SN06 is up
[2024-12-16T10:54:11.313+0000] {transport.py:1944} INFO - Connected (version 2.0, client OpenSSH_8.2p1)
[2024-12-16T10:54:11.382+0000] {transport.py:1944} INFO - Authentication (publickey) successful!
[2024-12-16T10:54:12.303+0000] {logging_mixin.py:190} INFO - Server 1rdLack SN07 is up
[2024-12-16T10:54:12.332+0000] {transport.py:1944} INFO - Connected (version 2.0, client OpenSSH_8.2p1)
[2024-12-16T10:54:12.395+0000] {transport.py:1944} INFO - Authentication (publickey) successful!
[2024-12-16T10:54:13.312+0000] {logging_mixin.py:190} INFO - Server 1rdLack SN09 is up
[2024-12-16T10:54:13.318+0000] {transport.py:1944} INFO - Connected (version 2.0, client OpenSSH_8.2p1)
[2024-12-16T10:54:13.368+0000] {transport.py:1944} INFO - Authentication (publickey) successful!
[2024-12-16T10:54:13.766+0000] {logging_mixin.py:190} INFO - Server cs1 is up
[2024-12-16T10:54:13.776+0000] {transport.py:1944} INFO - Connected (version 2.0, client OpenSSH_8.2p1)
[2024-12-16T10:54:13.885+0000] {transport.py:1944} INFO - Authentication (publickey) successful!
[2024-12-16T10:54:14.056+0000] {logging_mixin.py:190} INFO - Server DL01 is up
[2024-12-16T10:54:14.063+0000] {transport.py:1944} INFO - Connected (version 2.0, client OpenSSH_8.2p1)
[2024-12-16T10:54:14.167+0000] {transport.py:1944} INFO - Authentication (publickey) successful!
[2024-12-16T10:54:14.335+0000] {logging_mixin.py:190} INFO - Server DL02 is up
[2024-12-16T10:54:14.348+0000] {transport.py:1944} INFO - Connected (version 2.0, client OpenSSH_8.2p1)
[2024-12-16T10:54:14.453+0000] {transport.py:1944} INFO - Authentication (publickey) successful!
[2024-12-16T10:54:14.589+0000] {logging_mixin.py:190} INFO - Server DL03 is up
[2024-12-16T10:54:17.595+0000] {taskinstance.py:3311} ERROR - Task failed with exception
Traceback (most recent call last):
  File "/opt/airflow/dags/check_server_status.py", line 30, in check_server_status_ssh
    ssh_client.connect(server_ip, port=port, username=user_name, key_filename=private_key_path)
  File "/home/airflow/.local/lib/python3.12/site-packages/paramiko/client.py", line 409, in connect
    raise NoValidConnectionsError(errors)
paramiko.ssh_exception.NoValidConnectionsError: [Errno None] Unable to connect to port 10108 on 10.14.30.77

During handling of the above exception, another exception occurred:

Traceback (most recent call last):
  File "/home/airflow/.local/lib/python3.12/site-packages/airflow/models/taskinstance.py", line 767, in _execute_task
    result = _execute_callable(context=context, **execute_callable_kwargs)
             ^^^^^^^^^^^^^^^^^^^^^^^^^^^^^^^^^^^^^^^^^^^^^^^^^^^^^^^^^^^^^
  File "/home/airflow/.local/lib/python3.12/site-packages/airflow/models/taskinstance.py", line 733, in _execute_callable
    return ExecutionCallableRunner(
           ^^^^^^^^^^^^^^^^^^^^^^^^
  File "/home/airflow/.local/lib/python3.12/site-packages/airflow/utils/operator_helpers.py", line 252, in run
    return self.func(*args, **kwargs)
           ^^^^^^^^^^^^^^^^^^^^^^^^^^
  File "/home/airflow/.local/lib/python3.12/site-packages/airflow/models/baseoperator.py", line 417, in wrapper
    return func(self, *args, **kwargs)
           ^^^^^^^^^^^^^^^^^^^^^^^^^^^
  File "/home/airflow/.local/lib/python3.12/site-packages/airflow/operators/python.py", line 238, in execute
    return_value = self.execute_callable()
                   ^^^^^^^^^^^^^^^^^^^^^^^
  File "/home/airflow/.local/lib/python3.12/site-packages/airflow/operators/python.py", line 256, in execute_callable
    return runner.run(*self.op_args, **self.op_kwargs)
           ^^^^^^^^^^^^^^^^^^^^^^^^^^^^^^^^^^^^^^^^^^^
  File "/home/airflow/.local/lib/python3.12/site-packages/airflow/utils/operator_helpers.py", line 252, in run
    return self.func(*args, **kwargs)
           ^^^^^^^^^^^^^^^^^^^^^^^^^^
  File "/opt/airflow/dags/check_server_status.py", line 53, in check_server
    check_server_status_ssh(servers[i]['ip'], servers[i]['username'], servers[i]['port'], servers[i]['name'])
  File "/opt/airflow/dags/check_server_status.py", line 40, in check_server_status_ssh
    alert_to_discord(name, server_ip)
TypeError: alert_to_discord() takes 1 positional argument but 2 were given
[2024-12-16T10:54:17.606+0000] {logging_mixin.py:190} INFO - Task instance in failure state
[2024-12-16T10:54:17.607+0000] {logging_mixin.py:190} INFO - Task start:2024-12-16 10:54:01.620507+00:00 end:2024-12-16 10:54:17.606640+00:00 duration:15.986133
[2024-12-16T10:54:17.607+0000] {logging_mixin.py:190} INFO - Task:<Task(PythonOperator): check_server_status> dag:<DAG: check_server_status> dagrun:<DagRun check_server_status @ 2024-12-16 10:53:00+00:00: scheduled__2024-12-16T10:53:00+00:00, state:running, queued_at: 2024-12-16 10:54:00.075018+00:00. externally triggered: False>
[2024-12-16T10:54:17.607+0000] {logging_mixin.py:190} INFO - Failure caused by alert_to_discord() takes 1 positional argument but 2 were given
[2024-12-16T10:54:17.607+0000] {taskinstance.py:1225} INFO - Marking task as UP_FOR_RETRY. dag_id=check_server_status, task_id=check_server_status, run_id=scheduled__2024-12-16T10:53:00+00:00, execution_date=20241216T105300, start_date=20241216T105401, end_date=20241216T105417
[2024-12-16T10:54:17.623+0000] {taskinstance.py:340} INFO - ::group::Post task execution logs
[2024-12-16T10:54:17.623+0000] {standard_task_runner.py:124} ERROR - Failed to execute job 98 for task check_server_status (alert_to_discord() takes 1 positional argument but 2 were given; 365)
Traceback (most recent call last):
  File "/opt/airflow/dags/check_server_status.py", line 30, in check_server_status_ssh
    ssh_client.connect(server_ip, port=port, username=user_name, key_filename=private_key_path)
  File "/home/airflow/.local/lib/python3.12/site-packages/paramiko/client.py", line 409, in connect
    raise NoValidConnectionsError(errors)
paramiko.ssh_exception.NoValidConnectionsError: [Errno None] Unable to connect to port 10108 on 10.14.30.77

During handling of the above exception, another exception occurred:

Traceback (most recent call last):
  File "/home/airflow/.local/lib/python3.12/site-packages/airflow/task/task_runner/standard_task_runner.py", line 117, in _start_by_fork
    ret = args.func(args, dag=self.dag)
          ^^^^^^^^^^^^^^^^^^^^^^^^^^^^^
  File "/home/airflow/.local/lib/python3.12/site-packages/airflow/cli/cli_config.py", line 49, in command
    return func(*args, **kwargs)
           ^^^^^^^^^^^^^^^^^^^^^
  File "/home/airflow/.local/lib/python3.12/site-packages/airflow/utils/cli.py", line 116, in wrapper
    return f(*args, **kwargs)
           ^^^^^^^^^^^^^^^^^^
  File "/home/airflow/.local/lib/python3.12/site-packages/airflow/cli/commands/task_command.py", line 483, in task_run
    task_return_code = _run_task_by_selected_method(args, _dag, ti)
                       ^^^^^^^^^^^^^^^^^^^^^^^^^^^^^^^^^^^^^^^^^^^^
  File "/home/airflow/.local/lib/python3.12/site-packages/airflow/cli/commands/task_command.py", line 256, in _run_task_by_selected_method
    return _run_raw_task(args, ti)
           ^^^^^^^^^^^^^^^^^^^^^^^
  File "/home/airflow/.local/lib/python3.12/site-packages/airflow/cli/commands/task_command.py", line 341, in _run_raw_task
    return ti._run_raw_task(
           ^^^^^^^^^^^^^^^^^
  File "/home/airflow/.local/lib/python3.12/site-packages/airflow/utils/session.py", line 97, in wrapper
    return func(*args, session=session, **kwargs)
           ^^^^^^^^^^^^^^^^^^^^^^^^^^^^^^^^^^^^^^
  File "/home/airflow/.local/lib/python3.12/site-packages/airflow/models/taskinstance.py", line 3005, in _run_raw_task
    return _run_raw_task(
           ^^^^^^^^^^^^^^
  File "/home/airflow/.local/lib/python3.12/site-packages/airflow/models/taskinstance.py", line 273, in _run_raw_task
    TaskInstance._execute_task_with_callbacks(
  File "/home/airflow/.local/lib/python3.12/site-packages/airflow/models/taskinstance.py", line 3159, in _execute_task_with_callbacks
    result = self._execute_task(context, task_orig)
             ^^^^^^^^^^^^^^^^^^^^^^^^^^^^^^^^^^^^^^
  File "/home/airflow/.local/lib/python3.12/site-packages/airflow/models/taskinstance.py", line 3183, in _execute_task
    return _execute_task(self, context, task_orig)
           ^^^^^^^^^^^^^^^^^^^^^^^^^^^^^^^^^^^^^^^
  File "/home/airflow/.local/lib/python3.12/site-packages/airflow/models/taskinstance.py", line 767, in _execute_task
    result = _execute_callable(context=context, **execute_callable_kwargs)
             ^^^^^^^^^^^^^^^^^^^^^^^^^^^^^^^^^^^^^^^^^^^^^^^^^^^^^^^^^^^^^
  File "/home/airflow/.local/lib/python3.12/site-packages/airflow/models/taskinstance.py", line 733, in _execute_callable
    return ExecutionCallableRunner(
           ^^^^^^^^^^^^^^^^^^^^^^^^
  File "/home/airflow/.local/lib/python3.12/site-packages/airflow/utils/operator_helpers.py", line 252, in run
    return self.func(*args, **kwargs)
           ^^^^^^^^^^^^^^^^^^^^^^^^^^
  File "/home/airflow/.local/lib/python3.12/site-packages/airflow/models/baseoperator.py", line 417, in wrapper
    return func(self, *args, **kwargs)
           ^^^^^^^^^^^^^^^^^^^^^^^^^^^
  File "/home/airflow/.local/lib/python3.12/site-packages/airflow/operators/python.py", line 238, in execute
    return_value = self.execute_callable()
                   ^^^^^^^^^^^^^^^^^^^^^^^
  File "/home/airflow/.local/lib/python3.12/site-packages/airflow/operators/python.py", line 256, in execute_callable
    return runner.run(*self.op_args, **self.op_kwargs)
           ^^^^^^^^^^^^^^^^^^^^^^^^^^^^^^^^^^^^^^^^^^^
  File "/home/airflow/.local/lib/python3.12/site-packages/airflow/utils/operator_helpers.py", line 252, in run
    return self.func(*args, **kwargs)
           ^^^^^^^^^^^^^^^^^^^^^^^^^^
  File "/opt/airflow/dags/check_server_status.py", line 53, in check_server
    check_server_status_ssh(servers[i]['ip'], servers[i]['username'], servers[i]['port'], servers[i]['name'])
  File "/opt/airflow/dags/check_server_status.py", line 40, in check_server_status_ssh
    alert_to_discord(name, server_ip)
TypeError: alert_to_discord() takes 1 positional argument but 2 were given
[2024-12-16T10:54:17.665+0000] {local_task_job_runner.py:266} INFO - Task exited with return code 1
[2024-12-16T10:54:17.842+0000] {taskinstance.py:3895} INFO - 0 downstream tasks scheduled from follow-on schedule check
[2024-12-16T10:54:17.853+0000] {local_task_job_runner.py:245} INFO - ::endgroup::
